Workbook
Name Daily_C12_F13: Daily!$C$12:$F$13
Name Daily_C2_F3: Daily!$C$2:$F$3
Name Daily_C21_F22: Daily!$C$21:$F$22
Name Daily_C31_F32: Daily!$C$31:$F$32
Name Daily_L2_M3: Daily!$L$2:$M$3
Name Line_Stop_Prod_Loss_B23_O24: 'Line Stop_Prod Loss'!$B$23:$O$24
Name Line_Stop_Prod_Loss_B4_O5: 'Line Stop_Prod Loss'!$B$4:$O$5
Name Line_Stop_Prod_Loss_B43_M44: 'Line Stop_Prod Loss'!$B$43:$M$44
Name Monthly_C11_F12: Monthly!$C$11:$F$12
Name Monthly_C2_F3: Monthly!$C$2:$F$3
Name Monthly_C21_F22: Monthly!$C$21:$F$22
Name Monthly_C31_F32: Monthly!$C$31:$F$32
Name MTD_C11_F12: MTD!$C$11:$F$12
Name MTD_C2_F3: MTD!$C$2:$F$3
Name PrevFY_C11_F12: PrevFY!$C$11:$F$12
Name PrevFY_C2_F3: PrevFY!$C$2:$F$3
Name PrevFY_C21_F22: PrevFY!$C$21:$F$22
Name PrevFY_C31_F32: PrevFY!$C$31:$F$32
Name Weely_C11_M12: Weely!$C$11:$M$12
Name Weely_C2_M3: Weely!$C$2:$M$3
Name Weely_C21_M22: Weely!$C$21:$M$22
Name Weely_C31_M32: Weely!$C$31:$M$32
Name YTD_C11_F12: YTD!$C$11:$F$12
Name YTD_C2_F3: YTD!$C$2:$F$3
Name YTD_C21_F22: YTD!$C$21:$F$22
Name YTD_C31_F32: YTD!$C$31:$F$32

Sheet SQL Work
A1: MANAGEMENT PRODUCTION REPORT
P4: Month | U4: =Monthly!C12 -> 0
P5: Available Working Days | U5: =Daily!L3 -> 0
A6: Date | B6: 26-05-2026 | P6: Working Days Left | U6: =Daily!M3 -> 0
A7: Time | B7: 0.9375
E8: Monthly | I8: Weekly | N8: Daily | Q8: MTD | T8: YTD | U8: FY
E9: =Monthly!C12 -> 0 | I9: Week Actual | N9: =Daily!C3 -> 0 | Q9: =Daily!C13 -> 0 | T9: =YTD!C12 -> 0 | U9: =PrevFY!C12 -> 0
A10: MTD Rollout | E10: Plan | F10: Act | G10: Var | I10: W1 | J10: W2 | K10: W3 | L10: W4 | M10: W5 | N10: Plan | O10: Act | P10: Var | Q10: Plan | R10: Act | S10: Var | T10: Act | U10: Act
A11: Saarthi D+6 | E11: =Monthly!D12 -> 0 | F11: =Monthly!E12 -> 0 | G11: =Monthly!F12 -> 0 | I11: =Weely!E12 -> 0 | J11: =Weely!G12 -> 0 | K11: =Weely!I12 -> 0 | L11: =Weely!K12 -> 0 | M11: =Weely!M12 -> 0 | N11: =Daily!D13 -> 0 | O11: =Daily!E13 -> 0 | P11: =Daily!F13 -> 0 | Q11: =MTD!D12 -> 0 | R11: =MTD!E12 -> 0 | S11: =MTD!F12 -> 0 | T11: =YTD!E12 -> 0 | U11: =PrevFY!E12 -> 0
A12: Micky D+3 | E12: =Monthly!D3 -> 0 | F12: =Monthly!E3 -> 0 | G12: =Monthly!F3 -> 0 | I12: =Weely!E3 -> 0 | J12: =Weely!G3 -> 0 | K12: =Weely!I3 -> 0 | L12: =Weely!K3 -> 0 | M12: =Weely!M3 -> 0 | N12: =Daily!D3 -> 0 | O12: =Daily!E3 -> 0 | P12: =Daily!F3 -> 0 | Q12: =MTD!D3 -> 0 | R12: =MTD!E3 -> 0 | S12: =MTD!F3 -> 0 | T12: =YTD!E3 -> 0 | U12: =PrevFY!E3 -> 0
A13: Cargo | E13: =Monthly!D4 -> 0 | F13: =Monthly!E4 -> 0 | G13: =Monthly!F4 -> 0 | I13: =Weely!E4 -> 0 | J13: =Weely!G4 -> 0 | K13: =Weely!I4 -> 0 | L13: =Weely!K4 -> 0 | M13: =Weely!M4 -> 0 | N13: =Daily!D4 -> 0 | O13: =Daily!E4 -> 0 | P13: =Daily!F4 -> 0 | Q13: =MTD!D4 -> 0 | R13: =MTD!E4 -> 0 | S13: =MTD!F4 -> 0 | T13: =YTD!E4 -> 0 | U13: =PrevFY!E4 -> 0
A14: I-Puma | E14: =Monthly!D5 -> 0 | F14: =Monthly!E5 -> 0 | G14: =Monthly!F5 -> 0 | I14: =Weely!E5 -> 0 | J14: =Weely!G5 -> 0 | K14: =Weely!I5 -> 0 | L14: =Weely!K5 -> 0 | M14: =Weely!M5 -> 0 | N14: =Daily!D5 -> 0 | O14: =Daily!E5 -> 0 | P14: =Daily!F5 -> 0 | Q14: =MTD!D5 -> 0 | R14: =MTD!E5 -> 0 | S14: =MTD!F5 -> 0 | T14: =YTD!E5 -> 0 | U14: =PrevFY!E5 -> 0
C15: FY 2025-26 | E15: =Monthly!C12 -> 0 | I15: Weekly Saarthi | N15: =Daily!C13 -> 0
A16: MTD Inventory Status: | C16: Saarthi | D16: Micky | E16: Saarthi | F16: Micky | G16: Saarthi MTD | H16: Micky MTD | I16: W1 | J16: W2 | K16: W3 | L16: W4 | M16: W5 | N16: Sarthi | O16: Micky | P16: Total
A17: Chassis | B17: Roll Out | C17: =PrevFY!E12 -> 0 | D17: =PrevFY!E3 -> 0 | E17: =Monthly!E12 -> 0 | F17: =Monthly!E3 -> 0 | G17: =YTD!E12 -> 0 | H17: =YTD!E3 -> 0 | I17: =Weely!E12 -> 0 | J17: =Weely!G12 -> 0 | K17: =Weely!I12 -> 0 | L17: =Weely!K12 -> 0 | M17: =Weely!M12 -> 0 | N17: =Daily!E13 -> 0 | O17: =Daily!E3 -> 0 | P17: =SUM(N17:O17) -> 0
A18: BIW | B18: Roll Out | C18: =PrevFY!E32 -> 0 | D18: =PrevFY!E22 -> 0 | E18: =Monthly!E32 -> 0 | F18: =Monthly!E22 -> 0 | G18: =YTD!E32 -> 0 | H18: =YTD!E22 -> 0 | I18: =Weely!E32 -> 0 | J18: =Weely!G32 -> 0 | K18: =Weely!I32 -> 0 | L18: =Weely!K32 -> 0 | M18: =Weely!M32 -> 0 | N18: =Daily!E32 -> 0 | O18: =Daily!E22 -> 0 | P18: =SUM(N18:O18) -> 0
I19: Weekly Micky
I20: W1 | J20: W2 | K20: W3 | L20: W4 | M20: W5
H21: Roll Out | I21: =Weely!E3 -> 0 | J21: =Weely!G3 -> 0 | K21: =Weely!I3 -> 0 | L21: =Weely!K3 -> 0 | M21: =Weely!M3 -> 0
I22: Weekly Cargo | N22: =Daily!C20 -> 0
A23: MTD Inventory Status: | C23: Cargo | D23: I-Puma | E23: Cargo | F23: I-Puma | G23: Cargo MTD | H23: I-Puma MTD | I23: W1 | J23: W2 | K23: W3 | L23: W4 | M23: W5 | N23: Cargo | O23: I-Puma | P23: Total
A24: Chassis | B24: Roll Out | C24: =PrevFY!E18 -> 0 | D24: =PrevFY!E9 -> 0 | E24: =Monthly!E18 -> 0 | F24: =Monthly!E9 -> 0 | G24: =YTD!E18 -> 0 | H24: =YTD!E9 -> 0 | I24: =Weely!E18 -> 0 | J24: =Weely!G18 -> 0 | K24: =Weely!I18 -> 0 | L24: =Weely!K18 -> 0 | M24: =Weely!M18 -> 0 | N24: =Daily!E19 -> 0 | O24: =Daily!E9 -> 0 | P24: =SUM(N24:O24) -> 0
A25: BIW | B25: Roll Out | C25: =PrevFY!E38 -> 0 | D25: =PrevFY!E28 -> 0 | E25: =Monthly!E38 -> 0 | F25: =Monthly!E28 -> 0 | G25: =YTD!E38 -> 0 | H25: =YTD!E28 -> 0 | I25: =Weely!E38 -> 0 | J25: =Weely!G38 -> 0 | K25: =Weely!I38 -> 0 | L25: =Weely!K38 -> 0 | M25: =Weely!M38 -> 0 | N25: =Daily!E38 -> 0 | O25: =Daily!E28 -> 0 | P25: =SUM(N25:O25) -> 0
I26: Weekly I-Puma
I27: W1 | J27: W2 | K27: W3 | L27: W4 | M27: W5
H28: Roll Out | I28: =Weely!E9 -> 0 | J28: =Weely!G9 -> 0 | K28: =Weely!I9 -> 0 | L28: =Weely!K9 -> 0 | M28: =Weely!M9 -> 0
A30: Chassis Line Status
A31: Shift | B31: Shift Start Time | C31: Shift End Time | D31: Station Number | E31: Shift Time (Min) | F31: Plan Down Time (Min) | G31: Production Count | H31: Production Loss (Min) | I31: Call Loss Process (Min) | J31: Call Loss Material (Min) | K31: Call Loss Quality (Min) | M31: Call Loss Maint (Min) | O31: Call Loss Other (Min) | Q31: Call Loss Remark | T31: Station Availability (%)
A32: G | B32: 8.3 | C32: 17.3 | D32: CH-10 | E32: =540-40-F32 -> 500 | F32: 0 | G32: 2 | H32: 10 | I32: 2 | J32: 1 | K32: 3 | M32: 4 | O32: 0 | Q32: AGV not start | T32: 90
A33: G | B33: 8.3 | C33: 17.3 | D33: CH-20 | E33: =540-40-F33 -> 490 | F33: 10 | T33: 88
A34: G | B34: 8.3 | C34: 17.3 | D34: CH-30 | E34: =540-40-F34 -> 490 | F34: 10 | T34: 92
A35: G | B35: 8.3 | C35: 17.3 | D35: CH-40 | E35: =540-40-F35 -> 490 | F35: 10 | T35: 84
A36: G | B36: 8.3 | C36: 17.3 | D36: CH-50 | E36: =540-40-F36 -> 490 | F36: 10 | T36: 86
A37: G | B37: 8.3 | C37: 17.3 | D37: CH-60 | E37: =540-40-F37 -> 490 | F37: 10 | T37: 89
H38: Data for Stn 31-36
A39: Station Call | E39: =Daily!C3 -> 0
E40: Daily ( Min )
A41: No of Minutes Lost | E41: Chassis | F41: Trim | G41: Saarthi Main | H41: Saarthi Sub | I41: I-PUMA Main | J41: I-PUMA Sub | K41: Cargo Main | M41: Cargo Sub | O41: Chassis Line Loss Reason | S41: Remark
A42: Process Call | E42: =I32+I33+I34+I35+I36+I37 -> 2 | F42: ='Line Stop_Prod Loss'!H5 -> 0 | G42: ='Line Stop_Prod Loss'!F5 -> 0 | H42: ='Line Stop_Prod Loss'!E5 -> 0 | I42: ='Line Stop_Prod Loss'!D5 -> 0 | J42: ='Line Stop_Prod Loss'!C5 -> 0 | K42: 0 | M42: 0 | O42: ABCDEFG
A43: Material Call | E43: ='Line Stop_Prod Loss'!G6 -> 0 | F43: ='Line Stop_Prod Loss'!H6 -> 0 | G43: ='Line Stop_Prod Loss'!F6 -> 0 | H43: ='Line Stop_Prod Loss'!E6 -> 0 | I43: ='Line Stop_Prod Loss'!D6 -> 0 | J43: ='Line Stop_Prod Loss'!C6 -> 0 | K43: 0 | M43: 0 | O43: ABCDEFG
...

Sheet PLC Work
A1: MANAGEMENT PRODUCTION REPORT
P4: Month | U4: =Monthly!C12 -> 0 | X4: Report SQL work and SCADA Tagging
P5: Available Working Days | U5: =Daily!L3 -> 0 | X5: PLC Logic for data logging value
A6: Date | B6: 26-05-2026 | P6: Working Days Left | U6: =Daily!M3 -> 0 | X6: SCADA / TAB Screen
A7: Time | B7: 0.9375
E8: Monthly | I8: Weekly | N8: Daily | Q8: MTD | T8: YTD | U8: FY
E9: =Monthly!C12 -> 0 | I9: Week Actual | N9: =Daily!C3 -> 0 | Q9: =Daily!C13 -> 0 | T9: =YTD!C12 -> 0 | U9: =PrevFY!C12 -> 0
A10: MTD Rollout | E10: Plan | F10: Act | G10: Var | I10: W1 | J10: W2 | K10: W3 | L10: W4 | M10: W5 | N10: Plan | O10: Act | P10: Var | Q10: Plan | R10: Act | S10: Var | T10: Act | U10: Act
A11: Sarthi D+6 | E11: =Monthly!D12 -> 0 | F11: =Monthly!E12 -> 0 | G11: =Monthly!F12 -> 0 | I11: =Weely!E12 -> 0 | J11: =Weely!G12 -> 0 | K11: =Weely!I12 -> 0 | L11: =Weely!K12 -> 0 | M11: =Weely!M12 -> 0 | N11: =Daily!D13 -> 0 | O11: =Daily!E13 -> 0 | P11: =Daily!F13 -> 0 | Q11: =MTD!D12 -> 0 | R11: =MTD!E12 -> 0 | S11: =MTD!F12 -> 0 | T11: =YTD!E12 -> 0 | U11: =PrevFY!E12 -> 0
A12: Micky D+3 | E12: =Monthly!D3 -> 0 | F12: =Monthly!E3 -> 0 | G12: =Monthly!F3 -> 0 | I12: =Weely!E3 -> 0 | J12: =Weely!G3 -> 0 | K12: =Weely!I3 -> 0 | L12: =Weely!K3 -> 0 | M12: =Weely!M3 -> 0 | N12: =Daily!D3 -> 0 | O12: =Daily!E3 -> 0 | P12: =Daily!F3 -> 0 | Q12: =MTD!D3 -> 0 | R12: =MTD!E3 -> 0 | S12: =MTD!F3 -> 0 | T12: =YTD!E3 -> 0 | U12: =PrevFY!E3 -> 0
A13: Cargo | E13: =Monthly!D4 -> 0 | F13: =Monthly!E4 -> 0 | G13: =Monthly!F4 -> 0 | I13: =Weely!E4 -> 0 | J13: =Weely!G4 -> 0 | K13: =Weely!I4 -> 0 | L13: =Weely!K4 -> 0 | M13: =Weely!M4 -> 0 | N13: =Daily!D4 -> 0 | O13: =Daily!E4 -> 0 | P13: =Daily!F4 -> 0 | Q13: =MTD!D4 -> 0 | R13: =MTD!E4 -> 0 | S13: =MTD!F4 -> 0 | T13: =YTD!E4 -> 0 | U13: =PrevFY!E4 -> 0
A14: I-Puma | E14: =Monthly!D5 -> 0 | F14: =Monthly!E5 -> 0 | G14: =Monthly!F5 -> 0 | I14: =Weely!E5 -> 0 | J14: =Weely!G5 -> 0 | K14: =Weely!I5 -> 0 | L14: =Weely!K5 -> 0 | M14: =Weely!M5 -> 0 | N14: =Daily!D5 -> 0 | O14: =Daily!E5 -> 0 | P14: =Daily!F5 -> 0 | Q14: =MTD!D5 -> 0 | R14: =MTD!E5 -> 0 | S14: =MTD!F5 -> 0 | T14: =YTD!E5 -> 0 | U14: =PrevFY!E5 -> 0
C15: FY 2025-26 | E15: =Monthly!C12 -> 0 | I15: Weekly Sarthi | N15: =Daily!C13 -> 0
A16: MTD Inventory Status: | C16: Sarthi | D16: Micky | E16: Sarthi | F16: Micky | G16: Sarthi MTD | H16: Micky MTD | I16: W1 | J16: W2 | K16: W3 | L16: W4 | M16: W5 | N16: Sarthi | O16: Micky | P16: Total
A17: Chassis | B17: Roll Out | C17: =PrevFY!E12 -> 0 | D17: =PrevFY!E3 -> 0 | E17: =Monthly!E12 -> 0 | F17: =Monthly!E3 -> 0 | G17: =YTD!E12 -> 0 | H17: =YTD!E3 -> 0 | I17: =Weely!E12 -> 0 | J17: =Weely!G12 -> 0 | K17: =Weely!I12 -> 0 | L17: =Weely!K12 -> 0 | M17: =Weely!M12 -> 0 | N17: =Daily!E13 -> 0 | O17: =Daily!E3 -> 0 | P17: =SUM(N17:O17) -> 0
A18: BIW | B18: Roll Out | C18: =PrevFY!E32 -> 0 | D18: =PrevFY!E22 -> 0 | E18: =Monthly!E32 -> 0 | F18: =Monthly!E22 -> 0 | G18: =YTD!E32 -> 0 | H18: =YTD!E22 -> 0 | I18: =Weely!E32 -> 0 | J18: =Weely!G32 -> 0 | K18: =Weely!I32 -> 0 | L18: =Weely!K32 -> 0 | M18: =Weely!M32 -> 0 | N18: =Daily!E32 -> 0 | O18: =Daily!E22 -> 0 | P18: =SUM(N18:O18) -> 0
I19: Weekly Micky
I20: W1 | J20: W2 | K20: W3 | L20: W4 | M20: W5
H21: Roll Out | I21: =Weely!E3 -> 0 | J21: =Weely!G3 -> 0 | K21: =Weely!I3 -> 0 | L21: =Weely!K3 -> 0 | M21: =Weely!M3 -> 0
I22: Weekly Cargo | N22: =Daily!C20 -> 0
A23: MTD Inventory Status: | C23: Cargo | D23: I-Puma | E23: Cargo | F23: I-Puma | G23: Cargo MTD | H23: I-Puma MTD | I23: W1 | J23: W2 | K23: W3 | L23: W4 | M23: W5 | N23: Cargo | O23: I-Puma | P23: Total
A24: Chassis | B24: Roll Out | C24: =PrevFY!E18 -> 0 | D24: =PrevFY!E9 -> 0 | E24: =Monthly!E18 -> 0 | F24: =Monthly!E9 -> 0 | G24: =YTD!E18 -> 0 | H24: =YTD!E9 -> 0 | I24: =Weely!E18 -> 0 | J24: =Weely!G18 -> 0 | K24: =Weely!I18 -> 0 | L24: =Weely!K18 -> 0 | M24: =Weely!M18 -> 0 | N24: =Daily!E19 -> 0 | O24: =Daily!E9 -> 0 | P24: =SUM(N24:O24) -> 0
A25: BIW | B25: Roll Out | C25: =PrevFY!E38 -> 0 | D25: =PrevFY!E28 -> 0 | E25: =Monthly!E38 -> 0 | F25: =Monthly!E28 -> 0 | G25: =YTD!E38 -> 0 | H25: =YTD!E28 -> 0 | I25: =Weely!E38 -> 0 | J25: =Weely!G38 -> 0 | K25: =Weely!I38 -> 0 | L25: =Weely!K38 -> 0 | M25: =Weely!M38 -> 0 | N25: =Daily!E38 -> 0 | O25: =Daily!E28 -> 0 | P25: =SUM(N25:O25) -> 0
I26: Weekly I-Puma
I27: W1 | J27: W2 | K27: W3 | L27: W4 | M27: W5
H28: Roll Out | I28: =Weely!E9 -> 0 | J28: =Weely!G9 -> 0 | K28: =Weely!I9 -> 0 | L28: =Weely!K9 -> 0 | M28: =Weely!M9 -> 0
A30: Chassis Line Status
A31: Shift | B31: Shift Start Time | C31: Shift End Time | D31: Station Number | E31: Shift Time (Min) | F31: Plan Down Time (Min) | G31: Production Count | H31: Production Loss (Min) | I31: Call Loss Process (Min) | J31: Call Loss Material (Min) | K31: Call Loss Quality (Min) | M31: Call Loss Maint (Min) | O31: Call Loss Other (Min) | Q31: Call Loss Remark | T31: Station Availability (%)
A32: G | B32: 8.3 | C32: 17.3 | D32: CH-10 | E32: =540-40-F32 -> 490 | F32: 10 | G32: 2 | H32: 10 | I32: 2 | J32: 1 | K32: 3 | M32: 4 | O32: 0 | Q32: AGV not start | T32: 90
A33: G | B33: 8.3 | C33: 17.3 | D33: CH-20 | E33: =540-40-F33 -> 490 | F33: 10 | T33: 88
A34: G | B34: 8.3 | C34: 17.3 | D34: CH-30 | E34: =540-40-F34 -> 490 | F34: 10 | T34: 92
A35: G | B35: 8.3 | C35: 17.3 | D35: CH-40 | E35: =540-40-F35 -> 490 | F35: 10 | T35: 84
A36: G | B36: 8.3 | C36: 17.3 | D36: CH-50 | E36: =540-40-F36 -> 490 | F36: 10 | T36: 86
A37: G | B37: 8.3 | C37: 17.3 | D37: CH-60 | E37: =540-40-F37 -> 490 | F37: 10 | T37: 89
A39: Station Call | E39: =Daily!C3 -> 0
E40: Daily ( Min )
A41: No of Minutes Lost | E41: Trim | F41: Chassis | G41: BIW Main | H41: BIW Sub | I41: I-PUMA Main | J41: I-PUMA Sub | K41: Cargo | M41: Cargo Sub | O41: Chassis Line Loss Reason
A42: Process Call | E42: ='Line Stop_Prod Loss'!H5 -> 0 | F42: =I32+I33+I34+I35+I36+I37 -> 2 | G42: ='Line Stop_Prod Loss'!F5 -> 0 | H42: ='Line Stop_Prod Loss'!E5 -> 0 | I42: ='Line Stop_Prod Loss'!D5 -> 0 | J42: ='Line Stop_Prod Loss'!C5 -> 0 | K42: 0 | M42: 0 | O42: ABCDEFG
A43: Material Call | E43: ='Line Stop_Prod Loss'!H6 -> 0 | F43: ='Line Stop_Prod Loss'!G6 -> 0 | G43: ='Line Stop_Prod Loss'!F6 -> 0 | H43: ='Line Stop_Prod Loss'!E6 -> 0 | I43: ='Line Stop_Prod Loss'!D6 -> 0 | J43: ='Line Stop_Prod Loss'!C6 -> 0 | K43: 0 | M43: 0 | O43: ABCDEFG
A44: Quality Call | E44: ='Line Stop_Prod Loss'!H7 -> 0 | F44: ='Line Stop_Prod Loss'!G7 -> 0 | G44: ='Line Stop_Prod Loss'!F7 -> 0 | H44: ='Line Stop_Prod Loss'!E7 -> 0 | I44: ='Line Stop_Prod Loss'!D7 -> 0 | J44: ='Line Stop_Prod Loss'!C7 -> 0 | K44: 0 | M44: 0 | O44: ABCDEFG
...

Sheet Work Activity
A3: Sr. No. | B3: Report Section | C3: Data Field | D3: Report development work | E3: Part Of earlier Report | F3: Target Date | G3: PLC Software work | H3: Target Date | I3: SCADA Software work | J3: Target Date
A4: 1 | B4: Production data | C4: Month | D4: Production month | E4: Yes
A5: 2 | C5: Available Working Days | D5: Month days excluding weekly off and holiday | E5: Yes | I5: Month weekly off and holiday entry screen on SCADA | J5: Shruti - 04/06/2026
A6: 3 | C6: Working Days Left | D6: Left days of month excluding weekly off and holiday | E6: Yes | J6: Anjum - 05/06/2026
A7: 4 | C7: Report date and time | D7: Report generation Date and Time | E7: New | I7: SCADA screen for report execution | J7: 46177
A8: 5 | C8: Daily Date | D8: Production date | E8: Yes
A9: 6 | C9: monthly Plan and actual production | D9: Total monthly Plan and Actual Production count (Last log value of the day and Sum for month data) | E9: Yes
A10: 7 | C10: Var Production | D10: Actual - Plan = Diff | E10: Yes
A11: 8 | C11: Weekly actual production | D11: Total weekly Actual Production count (Last log value of the day and Sum for week data) | E11: Yes
A12: 9 | C12: Daily plan and actual production | D12: Today's Plan and Actual value of Last log | E12: Yes | G12: Today's Plan and Actual value with Trigger
A13: 10 | C13: monthly Plan and actual production | D13: Total monthly Plan and Actual Production count (Last log value of the day and Sum for month data) | E13: Yes
A14: 11 | C14: Yearly plan and actual production | D14: Total yearly (April To March) Actual Production (Last log value of the day and Sum for Year data) | E14: Yes
A15: 12 | C15: Last Year actual production | D15: Total Last Year (April To March) Actual Production (Last log value of the day and Sum for Year data) | E15: Yes
A16: 13 | C16: Sarthi, Micky last year data | D16: Total Last year (April To March) Actual Production count (Last log value of the day and Sum for Year data) | E16: Yes
A17: 14 | C17: Sarthi, Micky selected month data | D17: Total monthly Plan and Actual Production count | E17: Yes
C18: Sarthi, Micky selected day data | D18: Today's Plan and Actual value of Last log | E18: Yes | G18: Today's Actual Sarthi BIW value with Trigger | H18: 46177
A19: 15 | C19: Cargo, I-puma last year data | D19: Total Last year (April To March) Actual Production count | E19: New
A20: 16 | C20: Cargo, I-puma selected month data | D20: Total monthly Target and Actual Production count | E20: New
A21: 17 | C21: Cargo, I-puma selected day data | D21: Today's Actual value of Last log | E21: New | G21: Today's Actual Cargo and I Puma BIW value with Trigger
A22: 18 | B22: Production Loss | C22: Shift, Shift Start and End Time | D22: Today's Shift details at shift start | E22: Yes
A23: 19 | C23: Plan Down Time | D23: Today's line plan down time last log value | E23: Yes | I23: Plan Down time entry field in SCADA | J23: 46177
A24: 20 | C24: Station Production loss Min | D24: Today's Prod Loss Sum value and convert in Min | E24: New | G24: Today's Station Prod Loss Calculation In PLC | H24: 46177
A25: 21 | C25: Station Call loss Min | D25: Today's Station Sum of call loss Min | E25: New | G25: Today's Station Call Loss Calculation In PLC | H25: 46178
A26: 22 | C26: Call loss Remark | D26: Today's Station Highest call loss Min remark | E26: New | I26: Remark entry field in TAB screen and Tag generation in SCADA | J26: 46179
A27: 23 | C27: Station Availability | D27: Today's Station Availability last log value | E27: New | G27: Today's Station Availability calculation in PLC | H27: 46178
A28: 24 | B28: Production Call Status | C28: Call Min | D28: Highest call value | E28: 2 Line New | G28: Cargo and I Puma logic
A29: 25 | C29: Chassis Line Loss Reason | D29: Remark for Highest Chassis call value | E29: New
A30: 26 | C30: Shift Time | D30: Trigger on shift start | E30: Yes | G30: Total Shift time-Lunch/Snacks time - Plan Down time
A31: 27 | C31: Production count | D31: Last log value of Station production count | E31: New | G31: Station Wise production count | H31: 46177
A32: 28 | C32: Welcome Screen on SCADA | I32: Welcome Screen | J32: 46178
A33: 29 | C33: Navigation screen on SCADA | I33: Navigation button screen | J33: 46178
A34: 30

Sheet Daily
B1: M_TCF
C2: {{Date}} : Date | D2: {{TargetCount}} : TargetCount | E2: {{ActualCount}} : ActualCount | F2: {{Difference}} : Difference | L2: {{total_working_days}} : total_working_days | M2: {{working_days_left}} : working_days_left
B11: S_TCF
C12: {{Date}} : Date | D12: {{TargetCount}} : TargetCount | E12: {{ActualCount}} : ActualCount | F12: {{Difference}} : Difference
B20: M_BIW
C21: {{Date}} : Date | D21: {{TargetCount}} : TargetCount | E21: {{ActualCount}} : ActualCount | F21: {{Difference}} : Difference
B30: S_BIW
C31: {{Date}} : Date | D31: {{TargetCount}} : TargetCount | E31: {{ActualCount}} : ActualCount | F31: {{Difference}} : Difference

Sheet Line Stop_Prod Loss
B2: Line Stop Daily
A4: 1 | B4: {{TypeOfCallText}} : TypeOfCallText | C4: {{I-Puma Sub_Minutes}} : I-Puma Sub_Minutes | D4: {{I-Puma Main_Minutes}} : I-Puma Main_Minutes | E4: {{BIW Sub_Minutes}} : BIW Sub_Minutes | F4: {{BIW Main_Minutes}} : BIW Main_Minutes | G4: {{Micky_Minutes}} : Micky_Minutes | H4: {{D+6_Minutes}} : D+6_Minutes | I4: {{Total_Minutes}} : Total_Minutes | J4: {{I-Puma Sub_TopReason1}} : I-Puma Sub_TopReason1 | K4: {{I-Puma Main_TopReason1}} : I-Puma Main_TopReason1 | L4: {{BIW Sub_TopReason1}} : BIW Sub_TopReason1 | M4: {{BIW Main_TopReason1}} : BIW Main_TopReason1 | N4: {{Micky_TopReason1}} : Micky_TopReason1 | O4: {{D+6_TopReason1}} : D+6_TopReason1
B21: Line Stop Monthly
A23: 2 | B23: {{TypeOfCallText}} : TypeOfCallText | C23: {{I-Puma Sub_Minutes}} : I-Puma Sub_Minutes | D23: {{I-Puma Main_Minutes}} : I-Puma Main_Minutes | E23: {{BIW Sub_Minutes}} : BIW Sub_Minutes | F23: {{BIW Main_Minutes}} : BIW Main_Minutes | G23: {{Micky_Minutes}} : Micky_Minutes | H23: {{D+6_Minutes}} : D+6_Minutes | I23: {{Total_Minutes}} : Total_Minutes | J23: {{I-Puma Sub_TopReason1}} : I-Puma Sub_TopReason1 | K23: {{I-Puma Main_TopReason1}} : I-Puma Main_TopReason1 | L23: {{BIW Sub_TopReason1}} : BIW Sub_TopReason1 | M23: {{BIW Main_TopReason1}} : BIW Main_TopReason1 | N23: {{Micky_TopReason1}} : Micky_TopReason1 | O23: {{D+6_TopReason1}} : D+6_TopReason1
B41: Prodction Loss
A43: 3 | B43: {{Shift}} : Shift | C43: {{ShiftStart}} : ShiftStart | D43: {{ShiftEnd}} : ShiftEnd | E43: {{ProdCount}} : ProdCount | F43: {{ProdLoss}} : ProdLoss | G43: {{ShiftTime}} : ShiftTime | H43: {{BreakTime}} : BreakTime | I43: {{LinePause}} : LinePause | J43: {{DownTime}} : DownTime | K43: {{ShiftWorkingTime}} : ShiftWorkingTime | L43: {{OEE}} : OEE | M43: {{DT}} : DT

Sheet Weely
B1: M_TCF
C2: {{Comment}} : Comment | D2: {{Week1_Target}} : Week1_Target | E2: {{Week1_Actual}} : Week1_Actual | F2: {{Week2_Target}} : Week2_Target | G2: {{Week2_Actual}} : Week2_Actual | H2: {{Week3_Target}} : Week3_Target | I2: {{Week3_Actual}} : Week3_Actual | J2: {{Week4_Target}} : Week4_Target | K2: {{Week4_Actual}} : Week4_Actual | L2: {{Week5_Target}} : Week5_Target | M2: {{Week5_Actual}} : Week5_Actual
B10: S_TCF
C11: {{Comment}} : Comment | D11: {{Week1_Target}} : Week1_Target | E11: {{Week1_Actual}} : Week1_Actual | F11: {{Week2_Target}} : Week2_Target | G11: {{Week2_Actual}} : Week2_Actual | H11: {{Week3_Target}} : Week3_Target | I11: {{Week3_Actual}} : Week3_Actual | J11: {{Week4_Target}} : Week4_Target | K11: {{Week4_Actual}} : Week4_Actual | L11: {{Week5_Target}} : Week5_Target | M11: {{Week5_Actual}} : Week5_Actual
B20: M_BIW
C21: {{Comment}} : Comment | D21: {{Week1_Target}} : Week1_Target | E21: {{Week1_Actual}} : Week1_Actual | F21: {{Week2_Target}} : Week2_Target | G21: {{Week2_Actual}} : Week2_Actual | H21: {{Week3_Target}} : Week3_Target | I21: {{Week3_Actual}} : Week3_Actual | J21: {{Week4_Target}} : Week4_Target | K21: {{Week4_Actual}} : Week4_Actual | L21: {{Week5_Target}} : Week5_Target | M21: {{Week5_Actual}} : Week5_Actual
B30: S_BIW
C31: {{Comment}} : Comment | D31: {{Week1_Target}} : Week1_Target | E31: {{Week1_Actual}} : Week1_Actual | F31: {{Week2_Target}} : Week2_Target | G31: {{Week2_Actual}} : Week2_Actual | H31: {{Week3_Target}} : Week3_Target | I31: {{Week3_Actual}} : Week3_Actual | J31: {{Week4_Target}} : Week4_Target | K31: {{Week4_Actual}} : Week4_Actual | L31: {{Week5_Target}} : Week5_Target | M31: {{Week5_Actual}} : Week5_Actual

Sheet Monthly
B1: M_TCF
C2: {{Month}} : Month | D2: {{MonthlyTarget}} : MonthlyTarget | E2: {{TotalRecords}} : TotalRecords | F2: {{Difference}} : Difference
B10: S_TCF
C11: {{Month}} : Month | D11: {{MonthlyTarget}} : MonthlyTarget | E11: {{TotalRecords}} : TotalRecords | F11: {{Difference}} : Difference
B20: M_BIW
C21: {{Month}} : Month | D21: {{MonthlyTarget}} : MonthlyTarget | E21: {{TotalRecords}} : TotalRecords | F21: {{Difference}} : Difference
B30: S_BIW
C31: {{Month}} : Month | D31: {{MonthlyTarget}} : MonthlyTarget | E31: {{TotalRecords}} : TotalRecords | F31: {{Difference}} : Difference

Sheet MTD
B1: M_TCF
C2: {{MonthToDate}} : MonthToDate | D2: {{MTD_Target}} : MTD_Target | E2: {{MTD_Records}} : MTD_Records | F2: {{Difference}} : Difference
B10: S_TCF
C11: {{MonthToDate}} : MonthToDate | D11: {{MTD_Target}} : MTD_Target | E11: {{MTD_Records}} : MTD_Records | F11: {{Difference}} : Difference

Sheet YTD
B1: M_TCF
C2: {{YearToDate}} : YearToDate | D2: {{YTD_Target}} : YTD_Target | E2: {{YTD_Records}} : YTD_Records | F2: {{Difference}} : Difference
B3: Micky | H3: =_xlfn.CONCAT(B3,C3) -> #NAME?
B10: S_TCF
C11: {{YearToDate}} : YearToDate | D11: {{YTD_Target}} : YTD_Target | E11: {{YTD_Records}} : YTD_Records | F11: {{Difference}} : Difference
B12: D+6 | H12: =_xlfn.CONCAT(B12,C12) -> #NAME?
B20: M_BIW
C21: {{YearToDate}} : YearToDate | D21: {{YTD_Target}} : YTD_Target | E21: {{YTD_Records}} : YTD_Records | F21: {{Difference}} : Difference
B30: S_BIW
C31: {{YearToDate}} : YearToDate | D31: {{YTD_Target}} : YTD_Target | E31: {{YTD_Records}} : YTD_Records | F31: {{Difference}} : Difference

Sheet PrevFY
B1: M_TCF
C2: {{FinancialYear}} : FinancialYear | D2: {{TotalTarget}} : TotalTarget | E2: {{TotalRecords}} : TotalRecords | F2: {{Difference}} : Difference
B3: FY | H3: =_xlfn.CONCAT(B3,C3) -> #NAME?
B10: S_TCF
C11: {{FinancialYear}} : FinancialYear | D11: {{TotalTarget}} : TotalTarget | E11: {{TotalRecords}} : TotalRecords | F11: {{Difference}} : Difference
B12: FY
B20: M_BIW
C21: {{FinancialYear}} : FinancialYear | D21: {{TotalTarget}} : TotalTarget | E21: {{TotalRecords}} : TotalRecords | F21: {{Difference}} : Difference
B22: FY
B30: S_BIW
C31: {{FinancialYear}} : FinancialYear | D31: {{TotalTarget}} : TotalTarget | E31: {{TotalRecords}} : TotalRecords | F31: {{Difference}} : Difference
B32: FY
