Workbook
Name Daily_C12_F13: Daily!$C$12:$F$13
Name Daily_C2_F3: Daily!$C$2:$F$3
Name Daily_C21_F22: Daily!$C$21:$F$22
Name Daily_C31_F32: Daily!$C$31:$F$32
Name Daily_L2_M3: Daily!$L$2:$M$3
Name Line_Stop_Prod_Loss_B23_O24: 'Line Stop_Prod Loss'!$B$23:$O$24
Name Line_Stop_Prod_Loss_B4_O5: 'Line Stop_Prod Loss'!$B$4:$O$5
Name Line_Stop_Prod_Loss_B43_M44: 'Line Stop_Prod Loss'!$B$43:$M$44
Name Monthly_C11_F12: Monthly!$C$11:$F$12
Name Monthly_C2_F3: Monthly!$C$2:$F$3
Name Monthly_C21_F22: Monthly!$C$21:$F$22
Name Monthly_C31_F32: Monthly!$C$31:$F$32
Name MTD_C11_F12: MTD!$C$11:$F$12
Name MTD_C2_F3: MTD!$C$2:$F$3
Name PrevFY_C11_F12: PrevFY!$C$11:$F$12
Name PrevFY_C2_F3: PrevFY!$C$2:$F$3
Name PrevFY_C21_F22: PrevFY!$C$21:$F$22
Name PrevFY_C31_F32: PrevFY!$C$31:$F$32
Name Weely_C11_M12: Weely!$C$11:$M$12
Name Weely_C2_M3: Weely!$C$2:$M$3
Name Weely_C21_M22: Weely!$C$21:$M$22
Name Weely_C31_M32: Weely!$C$31:$M$32
Name YTD_C11_F12: YTD!$C$11:$F$12
Name YTD_C2_F3: YTD!$C$2:$F$3
Name YTD_C21_F22: YTD!$C$21:$F$22
Name YTD_C31_F32: YTD!$C$31:$F$32

Sheet Manag Report
A1: MANAGEMENT PRODUCTION REPORT
A4: Date | B4: 09-06-2026 | P4: Month | U4: Jun 2026
A5: Time | B5: 0.69398981 | P5: Available Working Days | U5: =Daily!L3 -> 0
P6: Working Days Left | U6: =Daily!M3 -> 0
E8: Monthly | I8: Weekly | N8: Daily | Q8: MTD | T8: YTD | U8: FY
E9: Jun 2026 | I9: Week Actual | N9: 09-Jun-2026 | Q9: 09-Jun | T9: =YTD!C12 -> 0 | U9: =PrevFY!C12 -> 25-26
A10: MTD Rollout | E10: Plan | F10: Act | G10: Var | I10: W1 | J10: W2 | K10: W3 | L10: W4 | M10: W5 | N10: Plan | O10: Act | P10: Var | Q10: Plan | R10: Act | S10: Var | T10: Act | U10: Act
A11: Saarthi D+6 | E11: 70 | F11: 23 | G11: -47 | I11: 15 | J11: 8 | K11: 0 | L11: 0 | M11: 0 | N11: 10 | O11: 2 | P11: -8 | Q11: 70 | R11: 23 | S11: -47 | T11: 288 | U11: 68
A12: Micky D+3 | E12: 80 | F12: 29 | G12: -51 | I12: 24 | J12: 5 | K12: 0 | L12: 0 | M12: 0 | N12: 10 | O12: 1 | P12: -9 | Q12: 80 | R12: 29 | S12: -51 | T12: 366 | U12: 68
A13: Cargo | E13: =Monthly!D4 -> 0 | F13: =Monthly!E4 -> 0 | G13: =Monthly!F4 -> 0 | I13: =Weely!E4 -> 0 | J13: =Weely!G4 -> 0 | K13: =Weely!I4 -> 0 | L13: =Weely!K4 -> 0 | M13: =Weely!M4 -> 0 | N13: =Daily!D4 -> 0 | O13: =Daily!E4 -> 0 | P13: =Daily!F4 -> 0 | Q13: =MTD!D4 -> 0 | R13: =MTD!E4 -> 0 | S13: =MTD!F4 -> 0 | T13: =YTD!E4 -> 0 | U13: =PrevFY!E4 -> 0
A14: I-Puma | E14: =Monthly!D5 -> 0 | F14: =Monthly!E5 -> 0 | G14: =Monthly!F5 -> 0 | I14: =Weely!E5 -> 0 | J14: =Weely!G5 -> 0 | K14: =Weely!I5 -> 0 | L14: =Weely!K5 -> 0 | M14: =Weely!M5 -> 0 | N14: =Daily!D5 -> 0 | O14: =Daily!E5 -> 0 | P14: =Daily!F5 -> 0 | Q14: =MTD!D5 -> 0 | R14: =MTD!E5 -> 0 | S14: =MTD!F5 -> 0 | T14: =YTD!E5 -> 0 | U14: =PrevFY!E5 -> 0
C15: FY 25-26 | E15: Jun 2026 | I15: Weekly Saarthi | N15: 09-Jun-2026
C16: Saarthi | D16: Micky | E16: Saarthi | F16: Micky | G16: Saarthi MTD | H16: Micky MTD | I16: W1 | J16: W2 | K16: W3 | L16: W4 | M16: W5 | N16: Sarthi | O16: Micky | P16: Total
A17: Chassis | B17: Roll Out | C17: 68 | D17: 68 | E17: =Monthly!E12 -> 0 | F17: =Monthly!E3 -> 0 | G17: =YTD!E12 -> 0 | H17: =YTD!E3 -> 0 | I17: =Weely!E12 -> 0 | J17: =Weely!G12 -> 0 | K17: =Weely!I12 -> 0 | L17: =Weely!K12 -> 0 | M17: =Weely!M12 -> 0 | N17: =Daily!E13 -> 0 | O17: =Daily!E3 -> 0 | P17: =SUM(N17:O17) -> 0
A18: BIW | B18: Roll Out | C18: 68 | D18: 68 | E18: 4 | F18: 4 | G18: 4 | H18: 4 | I18: 0 | J18: 0 | K18: 0 | L18: 0 | M18: 0 | N18: 0 | O18: 0 | P18: =SUM(N18:O18) -> 0
I19: Weekly Micky
I20: W1 | J20: W2 | K20: W3 | L20: W4 | M20: W5
I21: 0 | J21: 0 | K21: 0 | L21: 0 | M21: 0
H22: Roll Out | I22: 0 | J22: 0 | K22: 0 | L22: 0 | M22: 0
I23: Weekly Cargo | N23: 09-Jun-2026
C24: Cargo | D24: I-Puma | E24: Cargo | F24: I-Puma | G24: Cargo MTD | H24: I-Puma MTD | I24: W1 | J24: W2 | K24: W3 | L24: W4 | M24: W5 | N24: Cargo | O24: I-Puma | P24: Total
A25: Chassis | B25: Roll Out | C25: =PrevFY!E18 -> 0 | D25: =PrevFY!E9 -> 0 | E25: =Monthly!E18 -> 0 | F25: =Monthly!E9 -> 0 | G25: =YTD!E18 -> 0 | H25: =YTD!E9 -> 0 | I25: =Weely!E18 -> 0 | J25: =Weely!G18 -> 0 | K25: =Weely!I18 -> 0 | L25: =Weely!K18 -> 0 | M25: =Weely!M18 -> 0 | N25: =Daily!E19 -> 0 | O25: =Daily!E9 -> 0 | P25: =SUM(N25:O25) -> 0
A26: BIW | B26: Roll Out | C26: =PrevFY!E38 -> 0 | D26: =PrevFY!E28 -> 0 | E26: =Monthly!E38 -> 0 | F26: =Monthly!E28 -> 0 | G26: =YTD!E38 -> 0 | H26: =YTD!E28 -> 0 | I26: =Weely!E38 -> 0 | J26: =Weely!G38 -> 0 | K26: =Weely!I38 -> 0 | L26: =Weely!K38 -> 0 | M26: =Weely!M38 -> 0 | N26: =Daily!E38 -> 0 | O26: =Daily!E28 -> 0 | P26: =SUM(N26:O26) -> 0
I27: Weekly I-Puma
I28: W1 | J28: W2 | K28: W3 | L28: W4 | M28: W5
I29: =Weely!E8 -> 0 | J29: =Weely!G8 -> 0 | K29: =Weely!I8 -> 0 | L29: =Weely!K8 -> 0 | M29: =Weely!M8 -> 0
H30: Roll Out | I30: =Weely!E9 -> 0 | J30: =Weely!G9 -> 0 | K30: =Weely!I9 -> 0 | L30: =Weely!K9 -> 0 | M30: =Weely!M9 -> 0
D32: Chassis Production Daily
D33: Shift | E33: Shift Start Time | F33: Shift End Time | G33: Shift Time (Min) | H33: Plan Down Time (Min) | I33: Production Count | J33: Station Availability (%)
D34: G | E34: 8.3 | F34: 17.3 | G34: 490 | H34: 10 | I34: 5 | J34: =IF(#REF!>0, ROUND((#REF!-#REF!)/#REF!*100, 0), 0) -> #REF!
H35: 40min break
A36: Chassis Line Status
A37: Station Number | B37: Production Loss (Min) | C37: Call Loss Process (Min) | D37: Call Loss Material (Min) | E37: Call Loss Quality (Min) | F37: Call Loss Maint (Min) | G37: Call Loss Other (Min) | H37: Call Loss Remark
A38: CH-10 | B38: 13 | C38: 0 | D38: 7.2 | E38: 5.4 | F38: 14.1 | G38: 0
A39: CH-20 | B39: 12 | C39: 0 | D39: 0 | E39: 0 | F39: 0 | G39: 0
A40: CH-30 | B40: 11 | C40: 0 | D40: 0 | E40: 0 | F40: 0 | G40: 0
A41: CH-40 | B41: 20 | C41: 67.6 | D41: 0 | E41: 0 | F41: 0 | G41: 0
A42: CH-50 | B42: 25 | C42: 0 | D42: 0 | E42: 0 | F42: 113.8 | G42: 0
A43: CH-60 | B43: 55 | C43: 166.7 | D43: 0 | E43: 0 | F43: 0 | G43: 0
A45: Station Call | E45: 46182
...

Sheet Daily
B1: M_TCF
C2: {{Date}} : Date | D2: {{TargetCount}} : TargetCount | E2: {{ActualCount}} : ActualCount | F2: {{Difference}} : Difference | L2: {{total_working_days}} : total_working_days | M2: {{working_days_left}} : working_days_left
B11: S_TCF
C12: {{Date}} : Date | D12: {{TargetCount}} : TargetCount | E12: {{ActualCount}} : ActualCount | F12: {{Difference}} : Difference
B20: M_BIW
C21: {{Date}} : Date | D21: {{TargetCount}} : TargetCount | E21: {{ActualCount}} : ActualCount | F21: {{Difference}} : Difference
B30: S_BIW
C31: {{Date}} : Date | D31: {{TargetCount}} : TargetCount | E31: {{ActualCount}} : ActualCount | F31: {{Difference}} : Difference

Sheet Line Stop_Prod Loss
B2: Line Stop Daily
A4: 1 | B4: {{TypeOfCallText}} : TypeOfCallText | C4: {{I-Puma Sub_Minutes}} : I-Puma Sub_Minutes | D4: {{I-Puma Main_Minutes}} : I-Puma Main_Minutes | E4: {{BIW Sub_Minutes}} : BIW Sub_Minutes | F4: {{BIW Main_Minutes}} : BIW Main_Minutes | G4: {{Micky_Minutes}} : Micky_Minutes | H4: {{D+6_Minutes}} : D+6_Minutes | I4: {{Total_Minutes}} : Total_Minutes | J4: {{I-Puma Sub_TopReason1}} : I-Puma Sub_TopReason1 | K4: {{I-Puma Main_TopReason1}} : I-Puma Main_TopReason1 | L4: {{BIW Sub_TopReason1}} : BIW Sub_TopReason1 | M4: {{BIW Main_TopReason1}} : BIW Main_TopReason1 | N4: {{Micky_TopReason1}} : Micky_TopReason1 | O4: {{D+6_TopReason1}} : D+6_TopReason1
B5: Process Call | C5: 0 | D5: 0 | E5: 0 | F5: 0 | G5: 0.5 | H5: 73.7 | I5: 74.1 | N5: Standard Work Problem
B6: Material Call | C6: 0 | D6: 0 | E6: 0 | F6: 0 | G6: 156.3 | H6: 0 | I6: 156.3 | N6: Material Shortage
B7: Quality Call | C7: 0 | D7: 0 | E7: 0 | F7: 0 | G7: 0 | H7: 0.2 | I7: 0.2
B8: Maintenance Call | C8: 0 | D8: 0 | E8: 0 | F8: 0 | G8: 0.1 | H8: 0.1 | I8: 0.2 | N8: Water Flow Issue
B9: Other | C9: 0 | D9: 0 | E9: 0 | F9: 0 | G9: 0 | H9: 0 | I9: 0
B21: Line Stop Monthly
A23: 2 | B23: {{TypeOfCallText}} : TypeOfCallText | C23: {{I-Puma Sub_Minutes}} : I-Puma Sub_Minutes | D23: {{I-Puma Main_Minutes}} : I-Puma Main_Minutes | E23: {{BIW Sub_Minutes}} : BIW Sub_Minutes | F23: {{BIW Main_Minutes}} : BIW Main_Minutes | G23: {{Micky_Minutes}} : Micky_Minutes | H23: {{D+6_Minutes}} : D+6_Minutes | I23: {{Total_Minutes}} : Total_Minutes | J23: {{I-Puma Sub_TopReason1}} : I-Puma Sub_TopReason1 | K23: {{I-Puma Main_TopReason1}} : I-Puma Main_TopReason1 | L23: {{BIW Sub_TopReason1}} : BIW Sub_TopReason1 | M23: {{BIW Main_TopReason1}} : BIW Main_TopReason1 | N23: {{Micky_TopReason1}} : Micky_TopReason1 | O23: {{D+6_TopReason1}} : D+6_TopReason1
B24: Process Call | C24: 0 | D24: 0 | E24: 0 | F24: 0 | G24: 19.6 | H24: 974.8 | I24: 994.4 | N24: Information/Instruction Needed | O24: Work Imbalance
B25: Material Call | C25: 0 | D25: 0 | E25: 0 | F25: 0 | G25: 1219.1 | H25: 89.8 | I25: 1308.9 | N25: Material Shortage | O25: Material Shortage
B26: Quality Call | C26: 0 | D26: 0 | E26: 0 | F26: 0 | G26: 0.2 | H26: 111.6 | I26: 111.8 | N26: Defect Created | O26: Part Issue
B27: Maintenance Call | C27: 0 | D27: 0 | E27: 0 | F27: 0 | G27: 0.4 | H27: 12.7 | I27: 13 | N27: Spare1 | O27: Air Pressure Drop
B28: Other | C28: 0 | D28: 0 | E28: 0 | F28: 0 | G28: 0 | H28: 0 | I28: 0
B41: Prodction Loss
A43: 3

Sheet Weely
B1: M_TCF
C2: {{Comment}} : Comment | D2: {{Week1_Target}} : Week1_Target | E2: {{Week1_Actual}} : Week1_Actual | F2: {{Week2_Target}} : Week2_Target | G2: {{Week2_Actual}} : Week2_Actual | H2: {{Week3_Target}} : Week3_Target | I2: {{Week3_Actual}} : Week3_Actual | J2: {{Week4_Target}} : Week4_Target | K2: {{Week4_Actual}} : Week4_Actual | L2: {{Week5_Target}} : Week5_Target | M2: {{Week5_Actual}} : Week5_Actual
B10: S_TCF
C11: {{Comment}} : Comment | D11: {{Week1_Target}} : Week1_Target | E11: {{Week1_Actual}} : Week1_Actual | F11: {{Week2_Target}} : Week2_Target | G11: {{Week2_Actual}} : Week2_Actual | H11: {{Week3_Target}} : Week3_Target | I11: {{Week3_Actual}} : Week3_Actual | J11: {{Week4_Target}} : Week4_Target | K11: {{Week4_Actual}} : Week4_Actual | L11: {{Week5_Target}} : Week5_Target | M11: {{Week5_Actual}} : Week5_Actual
B20: M_BIW
C21: {{Comment}} : Comment | D21: {{Week1_Target}} : Week1_Target | E21: {{Week1_Actual}} : Week1_Actual | F21: {{Week2_Target}} : Week2_Target | G21: {{Week2_Actual}} : Week2_Actual | H21: {{Week3_Target}} : Week3_Target | I21: {{Week3_Actual}} : Week3_Actual | J21: {{Week4_Target}} : Week4_Target | K21: {{Week4_Actual}} : Week4_Actual | L21: {{Week5_Target}} : Week5_Target | M21: {{Week5_Actual}} : Week5_Actual
B30: S_BIW
C31: {{Comment}} : Comment | D31: {{Week1_Target}} : Week1_Target | E31: {{Week1_Actual}} : Week1_Actual | F31: {{Week2_Target}} : Week2_Target | G31: {{Week2_Actual}} : Week2_Actual | H31: {{Week3_Target}} : Week3_Target | I31: {{Week3_Actual}} : Week3_Actual | J31: {{Week4_Target}} : Week4_Target | K31: {{Week4_Actual}} : Week4_Actual | L31: {{Week5_Target}} : Week5_Target | M31: {{Week5_Actual}} : Week5_Actual

Sheet Monthly
B1: M_TCF
C2: {{Month}} : Month | D2: {{MonthlyTarget}} : MonthlyTarget | E2: {{TotalRecords}} : TotalRecords | F2: {{Difference}} : Difference
B10: S_TCF
C11: {{Month}} : Month | D11: {{MonthlyTarget}} : MonthlyTarget | E11: {{TotalRecords}} : TotalRecords | F11: {{Difference}} : Difference
B20: M_BIW
C21: {{Month}} : Month | D21: {{MonthlyTarget}} : MonthlyTarget | E21: {{TotalRecords}} : TotalRecords | F21: {{Difference}} : Difference
B30: S_BIW
C31: {{Month}} : Month | D31: {{MonthlyTarget}} : MonthlyTarget | E31: {{TotalRecords}} : TotalRecords | F31: {{Difference}} : Difference

Sheet MTD
B1: M_TCF
C2: {{MonthToDate}} : MonthToDate | D2: {{MTD_Target}} : MTD_Target | E2: {{MTD_Records}} : MTD_Records | F2: {{Difference}} : Difference
B10: S_TCF
C11: {{MonthToDate}} : MonthToDate | D11: {{MTD_Target}} : MTD_Target | E11: {{MTD_Records}} : MTD_Records | F11: {{Difference}} : Difference

Sheet YTD
B1: M_TCF
C2: {{YearToDate}} : YearToDate | D2: {{YTD_Target}} : YTD_Target | E2: {{YTD_Records}} : YTD_Records | F2: {{Difference}} : Difference
B3: Micky | H3: =_xlfn.CONCAT(B3,C3) -> Micky
B10: S_TCF
C11: {{YearToDate}} : YearToDate | D11: {{YTD_Target}} : YTD_Target | E11: {{YTD_Records}} : YTD_Records | F11: {{Difference}} : Difference
B12: D+6 | H12: =_xlfn.CONCAT(B12,C12) -> D+6
B20: M_BIW
C21: {{YearToDate}} : YearToDate | D21: {{YTD_Target}} : YTD_Target | E21: {{YTD_Records}} : YTD_Records | F21: {{Difference}} : Difference
B30: S_BIW
C31: {{YearToDate}} : YearToDate | D31: {{YTD_Target}} : YTD_Target | E31: {{YTD_Records}} : YTD_Records | F31: {{Difference}} : Difference

Sheet PrevFY
B1: M_TCF
C2: {{FinancialYear}} : FinancialYear | D2: {{TotalTarget}} : TotalTarget | E2: {{TotalRecords}} : TotalRecords | F2: {{Difference}} : Difference
B3: FY | C3: 25-26 | D3: 88 | E3: 68 | F3: =D3-E3 -> 20 | H3: =_xlfn.CONCAT(B3,C3) -> FY 25-26
B10: S_TCF
C11: {{FinancialYear}} : FinancialYear | D11: {{TotalTarget}} : TotalTarget | E11: {{TotalRecords}} : TotalRecords | F11: {{Difference}} : Difference
B12: FY | C12: 25-26 | D12: 88 | E12: 68 | F12: =D12-E12 -> 20
B20: M_BIW
C21: {{FinancialYear}} : FinancialYear | D21: {{TotalTarget}} : TotalTarget | E21: {{TotalRecords}} : TotalRecords | F21: {{Difference}} : Difference
B22: FY | C22: 25-26 | D22: 88 | E22: 68 | F22: =D22-E22 -> 20
B30: S_BIW
C31: {{FinancialYear}} : FinancialYear | D31: {{TotalTarget}} : TotalTarget | E31: {{TotalRecords}} : TotalRecords | F31: {{Difference}} : Difference
B32: FY | C32: 25-26 | D32: 88 | E32: 68 | F32: =D32-E32 -> 20
